Workbook

Sheet data
A1: country | B1: order_value_EUR | C1: cost | D1: date | E1: category | F1: customer_name | G1: sales_manager | H1: sales_rep | I1: device_type | J1: order_id | K1: x | L1: ym | M1: month | N1: year | O1: month_name | P1: Diff
A2: Sweden | B2: 17524.02 | C2: 14122.61 | D2: 43873 | E2: Books | F2: Goldner-Dibbert | G2: Maxie Marrow | H2: Madelon Bront | I2: Mobile | J2: 70-0511466 | L2: =YEAR(D2)*100+MONTH(D2) -> 202002 | M2: =MONTH(D2) -> 2 | N2: =YEAR(D2) -> 2020 | O2: =VLOOKUP(M2,month_lookup!A:B,2,FALSE) -> Feb | P2: =IF(N2=2020,B2,-B2) -> 17524.02
A3: Finland | B3: 116563.4 | C3: 92807.78 | D3: 43734 | E3: Games | F3: Hilll-Vandervort | G3: Hube Corey | H3: Wat Bowkley | I3: Mobile | J3: 28-6585323 | L3: =YEAR(D3)*100+MONTH(D3) -> 201909 | M3: =MONTH(D3) -> 9 | N3: =YEAR(D3) -> 2019 | O3: =VLOOKUP(M3,month_lookup!A:B,2,FALSE) -> Sep | P3: =IF(N3=2020,B3,-B3) -> -116563.4
A4: Portugal | B4: 296465.56 | C4: 257480.34 | D4: 43657 | E4: Clothing | F4: Larkin-Collier | G4: Celine Tumasian | H4: Smitty Culverhouse | I4: PC | J4: 58-7703341 | L4: =YEAR(D4)*100+MONTH(D4) -> 201907 | M4: =MONTH(D4) -> 7 | N4: =YEAR(D4) -> 2019 | O4: =VLOOKUP(M4,month_lookup!A:B,2,FALSE) -> Jul | P4: =IF(N4=2020,B4,-B4) -> -296465.56
A5: Portugal | B5: 74532.02 | C5: 59752.32 | D5: 43923 | E5: Beauty | F5: Hessel-Stiedemann | G5: Celine Tumasian | H5: Aurelie Wren | I5: PC | J5: 14-6700183 | L5: =YEAR(D5)*100+MONTH(D5) -> 202004 | M5: =MONTH(D5) -> 4 | N5: =YEAR(D5) -> 2020 | O5: =VLOOKUP(M5,month_lookup!A:B,2,FALSE) -> Apr | P5: =IF(N5=2020,B5,-B5) -> 74532.02
A6: Spain | B6: 178763.42 | C6: 146621.76 | D6: 43821 | E6: Games | F6: Johns and Sons | G6: Emalia Dinse | H6: Bertha Walbrook | I6: Tablet | J6: 15-8765160 | L6: =YEAR(D6)*100+MONTH(D6) -> 201912 | M6: =MONTH(D6) -> 12 | N6: =YEAR(D6) -> 2019 | O6: =VLOOKUP(M6,month_lookup!A:B,2,FALSE) -> Dec | P6: =IF(N6=2020,B6,-B6) -> -178763.42
A7: Spain | B7: 84900.24 | C7: 73701.9 | D7: 44026 | E7: Clothing | F7: Farrell, Swaniawski and Crist | G7: Emalia Dinse | H7: Perri Aldersley | I7: PC | J7: 60-6998932 | L7: =YEAR(D7)*100+MONTH(D7) -> 202007 | M7: =MONTH(D7) -> 7 | N7: =YEAR(D7) -> 2020 | O7: =VLOOKUP(M7,month_lookup!A:B,2,FALSE) -> Jul | P7: =IF(N7=2020,B7,-B7) -> 84900.24
A8: Portugal | B8: 71620.08 | C8: 62245.01 | D8: 43501 | E8: Books | F8: Schoen-Keeling | G8: Celine Tumasian | H8: Smitty Culverhouse | I8: PC | J8: 69-6259390 | L8: =YEAR(D8)*100+MONTH(D8) -> 201902 | M8: =MONTH(D8) -> 2 | N8: =YEAR(D8) -> 2019 | O8: =VLOOKUP(M8,month_lookup!A:B,2,FALSE) -> Feb | P8: =IF(N8=2020,B8,-B8) -> -71620.08
A9: UK | B9: 156585.22 | C9: 126599.15 | D9: 44073 | E9: Accessories | F9: Hermiston, Simonis and Wisoky | G9: Jessamine Apark | H9: Winny Agnolo | I9: PC | J9: 64-5761908 | L9: =YEAR(D9)*100+MONTH(D9) -> 202008 | M9: =MONTH(D9) -> 8 | N9: =YEAR(D9) -> 2020 | O9: =VLOOKUP(M9,month_lookup!A:B,2,FALSE) -> Aug | P9: =IF(N9=2020,B9,-B9) -> 156585.22
A10: Portugal | B10: 78461.13 | C10: 63537.82 | D10: 43961 | E10: Appliances | F10: Hessel-Stiedemann | G10: Celine Tumasian | H10: Smitty Culverhouse | I10: Mobile | J10: 91-4126746 | L10: =YEAR(D10)*100+MONTH(D10) -> 202005 | M10: =MONTH(D10) -> 5 | N10: =YEAR(D10) -> 2020 | O10: =VLOOKUP(M10,month_lookup!A:B,2,FALSE) -> May | P10: =IF(N10=2020,B10,-B10) -> 78461.13
A11: France | B11: 64827.8 | C11: 56043.63 | D11: 43485 | E11: Appliances | F11: Gislason-Stanton | G11: Othello Bowes | H11: Maighdiln Upcraft | I11: PC | J11: 62-3312495 | L11: =YEAR(D11)*100+MONTH(D11) -> 201901 | M11: =MONTH(D11) -> 1 | N11: =YEAR(D11) -> 2019 | O11: =VLOOKUP(M11,month_lookup!A:B,2,FALSE) -> Jan | P11: =IF(N11=2020,B11,-B11) -> -64827.8
A12: Sweden | B12: 142664.34 | C12: 120808.16 | D12: 43589 | E12: Appliances | F12: Swaniawski, Runolfsson and Green | G12: Maxie Marrow | H12: Madelon Bront | I12: PC | J12: 85-6625096 | L12: =YEAR(D12)*100+MONTH(D12) -> 201905 | M12: =MONTH(D12) -> 5 | N12: =YEAR(D12) -> 2019 | O12: =VLOOKUP(M12,month_lookup!A:B,2,FALSE) -> May | P12: =IF(N12=2020,B12,-B12) -> -142664.34
A13: UK | B13: 66673.19 | C13: 52811.83 | D13: 43519 | E13: Smartphones | F13: Gislason-Stanton | G13: Jessamine Apark | H13: Winny Agnolo | I13: PC | J13: 25-6368157 | L13: =YEAR(D13)*100+MONTH(D13) -> 201902 | M13: =MONTH(D13) -> 2 | N13: =YEAR(D13) -> 2019 | O13: =VLOOKUP(M13,month_lookup!A:B,2,FALSE) -> Feb | P13: =IF(N13=2020,B13,-B13) -> -66673.19
... A1001: Portugal | B1001: 107716.72 | C1001: 86679.64 | D1001: 43848 | E1001: Accessories | F1001: Jacobson, Marvin and Brown | G1001: Celine Tumasian | H1001: Brynn Dempster | I1001: Mobile | J1001: 61-3294149 | L1001: =YEAR(D1001)*100+MONTH(D1001) -> 202001 | M1001: =MONTH(D1001) -> 1 | N1001: =YEAR(D1001) -> 2020 | O1001: =VLOOKUP(M1001,month_lookup!A:B,2,FALSE) -> Jan | P1001: =IF(N1001=2020,B1001,-B1001) -> 107716.72

Sheet data_describe
A1: country | B1: Customer Origin Country
A2: order_value_EUR | B2: Order_value | C2: Discreet
A3: cost | B3: Cost of goods sold
A4: date | B4: date ordered
A5: category | B5: Product Category
A6: customer_name | B6: Customer Name
A7: sales_manager | B7: Sale Manager Name
A8: sales_rep | B8: Sale Representative Name
A9: device_type | B9: The device type customer used to order
A10: order_id | B10: unique order_id

Sheet month_lookup
A1: 1 | B1: Jan
A2: =A1+1 -> 2 | B2: Feb
A3: =A2+1 -> 3 | B3: Mar
A4: =A3+1 -> 4 | B4: Apr
A5: =A4+1 -> 5 | B5: May
A6: =A5+1 -> 6 | B6: Jun
A7: =A6+1 -> 7 | B7: Jul
A8: =A7+1 -> 8 | B8: Aug
A9: =A8+1 -> 9 | B9: Sep
A10: =A9+1 -> 10 | B10: Oct
A11: =A10+1 -> 11 | B11: Nov
A12: =A11+1 -> 12 | B12: Dec

Sheet 01_pt_sale_by_month
B1: Pivottable
B2: use Group date fields
K5: Sales by month (EUR)
A7: Month | B7: 2019 | C7: 2020 | D7: pctChange | K7: Month | L7: 2019 | M7: 2020 | N7: pctChange
A8: Jan | B8: 4516614.8 | C8: 5215699.8 | D8: =C8/B8-1 -> 0.15478075 | K8: Jan | L8: 4516614.8 | M8: 5215699.8 | N8: 0.15478075 | Z8: SALES BY MONTH
A9: Feb | B9: 2895563.9 | C9: 1959413 | D9: =C9/B9-1 -> -0.32330521 | K9: Feb | L9: 2895563.9 | M9: 1959413 | N9: -0.32330521 | Z9: Monthly sales in milEUR
A10: Mar | B10: 2521828 | C10: 3579943.8 | D10: =C10/B10-1 -> 0.41958288 | K10: Mar | L10: 2521828 | M10: 3579943.8 | N10: 0.41958288 | AA10: 2019 | AB10: 2020 | AC10: %pct
A11: Apr | B11: 4172236.8 | C11: 4069097.8 | D11: =C11/B11-1 -> -0.024720311 | K11: Apr | L11: 4172236.8 | M11: 4069097.8 | N11: -0.024720311 | Z11: Jan | AA11: =L8/1000000 -> 4.5166148 | AB11: =M8/1000000 -> 5.2156998 | AC11: 0.15478075
A12: May | B12: 3825682 | C12: 5537943.8 | D12: =C12/B12-1 -> 0.44757035 | K12: May | L12: 3825682 | M12: 5537943.8 | N12: 0.44757035 | Z12: Feb | AA12: =L9/1000000 -> 2.8955639 | AB12: =M9/1000000 -> 1.959413 | AC12: -0.32330521
A13: Jun | B13: 7692234.9 | C13: 7158137.9 | D13: =C13/B13-1 -> -0.069433272 | K13: Jun | L13: 7692234.9 | M13: 7158137.9 | N13: -0.069433272 | Z13: Mar | AA13: =L10/1000000 -> 2.521828 | AB13: =M10/1000000 -> 3.5799438 | AC13: 0.41958288
A14: Jul | B14: 6638609.2 | C14: 5242556.5 | D14: =C14/B14-1 -> -0.21029296 | K14: Jul | L14: 6638609.2 | M14: 5242556.5 | N14: -0.21029296 | Z14: Apr | AA14: =L11/1000000 -> 4.1722368 | AB14: =M11/1000000 -> 4.0690978 | AC14: -0.024720311
A15: Aug | B15: 3437450.1 | C15: 4714525.2 | D15: =C15/B15-1 -> 0.37151814 | K15: Aug | L15: 3437450.1 | M15: 4714525.2 | N15: 0.37151814 | Z15: May | AA15: =L12/1000000 -> 3.825682 | AB15: =M12/1000000 -> 5.5379438 | AC15: 0.44757035
A16: Sep | B16: 4870060.6 | C16: 3778141.4 | D16: =C16/B16-1 -> -0.2242106 | K16: Sep | L16: 4870060.6 | M16: 3778141.4 | N16: -0.2242106 | Z16: Jun | AA16: =L13/1000000 -> 7.6922349 | AB16: =M13/1000000 -> 7.1581379 | AC16: -0.069433272
A17: Oct | B17: 4372149.5 | C17: 4869726.9 | D17: =C17/B17-1 -> 0.1138061 | K17: Oct | L17: 4372149.5 | M17: 4869726.9 | N17: 0.1138061 | Z17: Jul | AA17: =L14/1000000 -> 6.6386092 | AB17: =M14/1000000 -> 5.2425565 | AC17: -0.21029296
A18: Nov | B18: 2961318.6 | C18: 4734730.1 | D18: =C18/B18-1 -> 0.59885874 | K18: Nov | L18: 2961318.6 | M18: 4734730.1 | N18: 0.59885874 | Z18: Aug | AA18: =L15/1000000 -> 3.4374501 | AB18: =M15/1000000 -> 4.7145252 | AC18: 0.37151814
A19: Dec | B19: 8713776 | C19: 5884298.3 | D19: =C19/B19-1 -> -0.32471316 | K19: Dec | L19: 8713776 | M19: 5884298.3 | N19: -0.32471316 | Z19: Sep | AA19: =L16/1000000 -> 4.8700606 | AB19: =M16/1000000 -> 3.7781414 | AC19: -0.2242106
B20: 56617524 | C20: 56744214 | D20: =C20/B20-1 -> 0.0022376448 | L20: 56617524 | M20: 56744214 | N20: 0.0022376448 | Z20: Oct | AA20: =L17/1000000 -> 4.3721495 | AB20: =M17/1000000 -> 4.8697269 | AC20: 0.1138061
Z21: Nov | AA21: =L18/1000000 -> 2.9613186 | AB21: =M18/1000000 -> 4.7347301 | AC21: 0.59885874
Z22: Dec | AA22: =L19/1000000 -> 8.713776 | AB22: =M19/1000000 -> 5.8842983 | AC22: -0.32471316
AA23: =SUM(AA11:AA22) -> 56.617524 | AB23: =M20/1000000 -> 56.744214 | AC23: 0.0022376448

Sheet 02_pivot_table_calculated_field
B2: Pivotable not using Group Date field
B3: Use calculated items
B4: Wrong total on calculated field
A6: Sum of order_value_EUR | B6: Column Labels
A7: Row Labels | B7: 2019 | C7: 2020
A8: 1 | B8: 4516614.8 | C8: 5215699.8
A9: 2 | B9: 2895563.9 | C9: 1959413
A10: 3 | B10: 2521828 | C10: 3579943.8
A11: 4 | B11: 4172236.8 | C11: 4069097.8
A12: 5 | B12: 3825682 | C12: 5537943.8
A13: 6 | B13: 7692234.9 | C13: 7158137.9
A14: 7 | B14: 6638609.2 | C14: 5242556.5
A15: 8 | B15: 3437450.1 | C15: 4714525.2
A16: 9 | B16: 4870060.6 | C16: 3778141.4
A17: 10 | B17: 4372149.5 | C17: 4869726.9
A18: 11 | B18: 2961318.6 | C18: 4734730.1
A19: 12 | B19: 8713776 | C19: 5884298.3
A20: Grand Total | B20: 56617524 | C20: 56744214

Sheet 03_pivot_table_show_value_as
B2: Pivotable not using Group Date field
B3: use Show value as
B6: Column Labels
B7: 2019 | C7: 2019 | D7: 2020 | E7: 2020
A8: Row Labels | B8: Sum of order_value_EUR | C8: Sum of order_value_EUR 2 | D8: Sum of order_value_EUR | E8: Sum of order_value_EUR 2
A9: 1 | B9: 4516614.8 | D9: 5215699.8 | E9: 0.15478075
A10: 2 | B10: 2895563.9 | D10: 1959413 | E10: -0.32330521
A11: 3 | B11: 2521828 | D11: 3579943.8 | E11: 0.41958288
A12: 4 | B12: 4172236.8 | D12: 4069097.8 | E12: -0.024720311
A13: 5 | B13: 3825682 | D13: 5537943.8 | E13: 0.44757035
A14: 6 | B14: 7692234.9 | D14: 7158137.9 | E14: -0.069433272
A15: 7 | B15: 6638609.2 | D15: 5242556.5 | E15: -0.21029296
A16: 8 | B16: 3437450.1 | D16: 4714525.2 | E16: 0.37151814
A17: 9 | B17: 4870060.6 | D17: 3778141.4 | E17: -0.2242106
A18: 10 | B18: 4372149.5 | D18: 4869726.9 | E18: 0.1138061
A19: 11 | B19: 2961318.6 | D19: 4734730.1 | E19: 0.59885874
A20: 12 | B20: 8713776 | D20: 5884298.3 | E20: -0.32471316
A21: Grand Total | B21: 56617524 | D21: 56744214 | E21: 0.0022376448

Sheet 04_tb_sumif
G1: Sales by month (EUR)
G2: Month | H2: 2019 | I2: 2020 | J2: pctChange
B3: 43466 | C3: =EOMONTH(B3,0) -> 43496 | D3: =EOMONTH(B3,11)+1 -> 43831 | E3: =EOMONTH(D3,0) -> 43861 | G3: Jan | H3: =SUMIFS(data!$C:$C,data!$D:$D,">="&B3,data!$D:$D,"<="&C3) -> 3792383.5 | I3: =SUMIFS(data!$C:$C,data!$D:$D,">="&D3,data!$D:$D,"<="&E3) -> 4291060.8 | J3: =I3/H3-1 -> 0.13149443
B4: =C3+1 -> 43497 | C4: =EOMONTH(B4,0) -> 43524 | D4: =EOMONTH(B4,11)+1 -> 43862 | E4: =EOMONTH(D4,0) -> 43890 | G4: Feb | H4: =SUMIFS(data!$C:$C,data!$D:$D,">="&B4,data!$D:$D,"<="&C4) -> 2402359 | I4: =SUMIFS(data!$C:$C,data!$D:$D,">="&D4,data!$D:$D,"<="&E4) -> 1643662.5 | J4: =I4/H4-1 -> -0.31581313
B5: =C4+1 -> 43525 | C5: =EOMONTH(B5,0) -> 43555 | D5: =EOMONTH(B5,11)+1 -> 43891 | E5: =EOMONTH(D5,0) -> 43921 | G5: Mar | H5: =SUMIFS(data!$C:$C,data!$D:$D,">="&B5,data!$D:$D,"<="&C5) -> 2092407.4 | I5: =SUMIFS(data!$C:$C,data!$D:$D,">="&D5,data!$D:$D,"<="&E5) -> 2983600.1 | J5: =I5/H5-1 -> 0.4259174
B6: =C5+1 -> 43556 | C6: =EOMONTH(B6,0) -> 43585 | D6: =EOMONTH(B6,11)+1 -> 43922 | E6: =EOMONTH(D6,0) -> 43951 | G6: Apr | H6: =SUMIFS(data!$C:$C,data!$D:$D,">="&B6,data!$D:$D,"<="&C6) -> 3479483.1 | I6: =SUMIFS(data!$C:$C,data!$D:$D,">="&D6,data!$D:$D,"<="&E6) -> 3372878.3 | J6: =I6/H6-1 -> -0.030638122
B7: =C6+1 -> 43586 | C7: =EOMONTH(B7,0) -> 43616 | D7: =EOMONTH(B7,11)+1 -> 43952 | E7: =EOMONTH(D7,0) -> 43982 | G7: May | H7: =SUMIFS(data!$C:$C,data!$D:$D,">="&B7,data!$D:$D,"<="&C7) -> 3177423.7 | I7: =SUMIFS(data!$C:$C,data!$D:$D,">="&D7,data!$D:$D,"<="&E7) -> 4623092.1 | J7: =I7/H7-1 -> 0.45498133
B8: =C7+1 -> 43617 | C8: =EOMONTH(B8,0) -> 43646 | D8: =EOMONTH(B8,11)+1 -> 43983 | E8: =EOMONTH(D8,0) -> 44012 | G8: Jun | H8: =SUMIFS(data!$C:$C,data!$D:$D,">="&B8,data!$D:$D,"<="&C8) -> 6386956.5 | I8: =SUMIFS(data!$C:$C,data!$D:$D,">="&D8,data!$D:$D,"<="&E8) -> 5971093.4 | J8: =I8/H8-1 -> -0.065111315
B9: =C8+1 -> 43647 | C9: =EOMONTH(B9,0) -> 43677 | D9: =EOMONTH(B9,11)+1 -> 44013 | E9: =EOMONTH(D9,0) -> 44043 | G9: Jul | H9: =SUMIFS(data!$C:$C,data!$D:$D,">="&B9,data!$D:$D,"<="&C9) -> 5554381.8 | I9: =SUMIFS(data!$C:$C,data!$D:$D,">="&D9,data!$D:$D,"<="&E9) -> 4402567.1 | J9: =I9/H9-1 -> -0.20737046
B10: =C9+1 -> 43678 | C10: =EOMONTH(B10,0) -> 43708 | D10: =EOMONTH(B10,11)+1 -> 44044 | E10: =EOMONTH(D10,0) -> 44074 | G10: Aug | H10: =SUMIFS(data!$C:$C,data!$D:$D,">="&B10,data!$D:$D,"<="&C10) -> 2857134 | I10: =SUMIFS(data!$C:$C,data!$D:$D,">="&D10,data!$D:$D,"<="&E10) -> 3945548.9 | J10: =I10/H10-1 -> 0.38094637
B11: =C10+1 -> 43709 | C11: =EOMONTH(B11,0) -> 43738 | D11: =EOMONTH(B11,11)+1 -> 44075 | E11: =EOMONTH(D11,0) -> 44104 | G11: Sep | H11: =SUMIFS(data!$C:$C,data!$D:$D,">="&B11,data!$D:$D,"<="&C11) -> 4081869 | I11: =SUMIFS(data!$C:$C,data!$D:$D,">="&D11,data!$D:$D,"<="&E11) -> 3114973.7 | J11: =I11/H11-1 -> -0.23687562
B12: =C11+1 -> 43739 | C12: =EOMONTH(B12,0) -> 43769 | D12: =EOMONTH(B12,11)+1 -> 44105 | E12: =EOMONTH(D12,0) -> 44135 | G12: Oct | H12: =SUMIFS(data!$C:$C,data!$D:$D,">="&B12,data!$D:$D,"<="&C12) -> 3627715.1 | I12: =SUMIFS(data!$C:$C,data!$D:$D,">="&D12,data!$D:$D,"<="&E12) -> 4030025.9 | J12: =I12/H12-1 -> 0.11089923
B13: =C12+1 -> 43770 | C13: =EOMONTH(B13,0) -> 43799 | D13: =EOMONTH(B13,11)+1 -> 44136 | E13: =EOMONTH(D13,0) -> 44165 | G13: Nov | H13: =SUMIFS(data!$C:$C,data!$D:$D,">="&B13,data!$D:$D,"<="&C13) -> 2479031 | I13: =SUMIFS(data!$C:$C,data!$D:$D,">="&D13,data!$D:$D,"<="&E13) -> 3947059.7 | J13: =I13/H13-1 -> 0.59217847
B14: =C13+1 -> 43800 | C14: =EOMONTH(B14,0) -> 43830 | D14: =EOMONTH(B14,11)+1 -> 44166 | E14: =EOMONTH(D14,0) -> 44196 | G14: Dec | H14: =SUMIFS(data!$C:$C,data!$D:$D,">="&B14,data!$D:$D,"<="&C14) -> 7199102.5 | I14: =SUMIFS(data!$C:$C,data!$D:$D,">="&D14,data!$D:$D,"<="&E14) -> 4913502 | J14: =I14/H14-1 -> -0.31748408
H15: 56617524 | I15: 56744214 | J15: =I15/H15-1 -> 0.0022376448

Sheet 05_sumproduct
A1: Month | B1: 2019 | C1: 2020 | D1: fake
A2: Jan | B2: {=SUMPRODUCT((data!D2:D1001>=43466)*(data!D2:D1001<43497)*data!B2:B1001)} -> 4516614.8 | C2: {=SUMPRODUCT((data!D2:D1001>=43831)*(data!D2:D1001<43862)*data!B2:B1001)} -> 5215699.8
A3: Feb | B3: {=SUMPRODUCT((data!D2:D1001>=43497)*(data!D2:D1001<43525)*data!B2:B1001)} -> 2895563.9 | C3: {=SUMPRODUCT((data!D2:D1001>=43862)*(data!D2:D1001<43891)*data!B2:B1001)} -> 1959413
A4: Mar | B4: {=SUMPRODUCT((data!D2:D1001>=43525)*(data!D2:D1001<43556)*data!B2:B1001)} -> 2521828 | C4: {=SUMPRODUCT((data!D2:D1001>=43891)*(data!D2:D1001<43922)*data!B2:B1001)} -> 3579943.8
A5: Apr | B5: {=SUMPRODUCT((data!D2:D1001>=43556)*(data!D2:D1001<43586)*data!B2:B1001)} -> 4172236.8 | C5: {=SUMPRODUCT((data!D2:D1001>=43922)*(data!D2:D1001<43952)*data!B2:B1001)} -> 4069097.8
A6: May | B6: {=SUMPRODUCT((data!D2:D1001>=43586)*(data!D2:D1001<43617)*data!B2:B1001)} -> 3825682 | C6: {=SUMPRODUCT((data!D2:D1001>=43952)*(data!D2:D1001<43983)*data!B2:B1001)} -> 5537943.8
A7: Jun | B7: {=SUMPRODUCT((data!D2:D1001>=43617)*(data!D2:D1001<43647)*data!B2:B1001)} -> 7692234.9 | C7: {=SUMPRODUCT((data!D2:D1001>=43983)*(data!D2:D1001<44013)*data!B2:B1001)} -> 7158137.9 | D7: 10000000
A8: Jul | B8: {=SUMPRODUCT((data!D2:D1001>=43647)*(data!D2:D1001<43678)*data!B2:B1001)} -> 6638609.2 | C8: {=SUMPRODUCT((data!D2:D1001>=44013)*(data!D2:D1001<44044)*data!B2:B1001)} -> 5242556.5 | D8: 10000000
A9: Aug | B9: {=SUMPRODUCT((data!D2:D1001>=43678)*(data!D2:D1001<43709)*data!B2:B1001)} -> 3437450.1 | C9: {=SUMPRODUCT((data!D2:D1001>=44044)*(data!D2:D1001<44075)*data!B2:B1001)} -> 4714525.2
A10: Sep | B10: {=SUMPRODUCT((data!D2:D1001>=43709)*(data!D2:D1001<43739)*data!B2:B1001)} -> 4870060.6 | C10: {=SUMPRODUCT((data!D2:D1001>=44075)*(data!D2:D1001<44105)*data!B2:B1001)} -> 3778141.4
A11: Oct | B11: {=SUMPRODUCT((data!D2:D1001>=43739)*(data!D2:D1001<43770)*data!B2:B1001)} -> 4372149.5 | C11: {=SUMPRODUCT((data!D2:D1001>=44105)*(data!D2:D1001<44136)*data!B2:B1001)} -> 4869726.9
A12: Nov | B12: {=SUMPRODUCT((data!D2:D1001>=43770)*(data!D2:D1001<43800)*data!B2:B1001)} -> 2961318.6 | C12: {=SUMPRODUCT((data!D2:D1001>=44136)*(data!D2:D1001<44166)*data!B2:B1001)} -> 4734730.1
A13: Dec | B13: {=SUMPRODUCT((data!D2:D1001>=43800)*(data!D2:D1001<43831)*data!B2:B1001)} -> 8713776 | C13: {=SUMPRODUCT((data!D2:D1001>=44166)*(data!D2:D1001<44197)*data!B2:B1001)} -> 5884298.3 | D13: 10000000 | E13: 2019 | F13: 2020
K25: Line chart
K26: Fake column for background
K27: Colors
K28: Data lable show series
K29: Legend custom number format

Sheet 06_chart_01
A1: Month | B1: 2019 | C1: 2020 | D1: fake | I1: Month | J1: Diff | K1: Net Acc Diff
A2: Jan | B2: {=SUMPRODUCT((data!D2:D1001>=43466)*(data!D2:D1001<43497)*data!B2:B1001)} -> 4516614.8 | C2: {=SUMPRODUCT((data!D2:D1001>=43831)*(data!D2:D1001<43862)*data!B2:B1001)} -> 5215699.8 | I2: Jan | J2: =C2-B2 -> 699085.01 | K2: =SUM($J$2:J2) -> 699085.01
A3: Feb | B3: {=SUMPRODUCT((data!D2:D1001>=43497)*(data!D2:D1001<43525)*data!B2:B1001)} -> 2895563.9 | C3: {=SUMPRODUCT((data!D2:D1001>=43862)*(data!D2:D1001<43891)*data!B2:B1001)} -> 1959413 | I3: Feb | J3: =C3-B3 -> -936150.9 | K3: =SUM($J$2:J3) -> -237065.89
A4: Mar | B4: {=SUMPRODUCT((data!D2:D1001>=43525)*(data!D2:D1001<43556)*data!B2:B1001)} -> 2521828 | C4: {=SUMPRODUCT((data!D2:D1001>=43891)*(data!D2:D1001<43922)*data!B2:B1001)} -> 3579943.8 | I4: Mar | J4: =C4-B4 -> 1058115.8 | K4: =SUM($J$2:J4) -> 821049.96
A5: Apr | B5: {=SUMPRODUCT((data!D2:D1001>=43556)*(data!D2:D1001<43586)*data!B2:B1001)} -> 4172236.8 | C5: {=SUMPRODUCT((data!D2:D1001>=43922)*(data!D2:D1001<43952)*data!B2:B1001)} -> 4069097.8 | I5: Apr | J5: =C5-B5 -> -103138.99 | K5: =SUM($J$2:J5) -> 717910.97
A6: May | B6: {=SUMPRODUCT((data!D2:D1001>=43586)*(data!D2:D1001<43617)*data!B2:B1001)} -> 3825682 | C6: {=SUMPRODUCT((data!D2:D1001>=43952)*(data!D2:D1001<43983)*data!B2:B1001)} -> 5537943.8 | I6: May | J6: =C6-B6 -> 1712261.8 | K6: =SUM($J$2:J6) -> 2430172.8
A7: Jun | B7: {=SUMPRODUCT((data!D2:D1001>=43617)*(data!D2:D1001<43647)*data!B2:B1001)} -> 7692234.9 | C7: {=SUMPRODUCT((data!D2:D1001>=43983)*(data!D2:D1001<44013)*data!B2:B1001)} -> 7158137.9 | D7: 10000000 | I7: Jun | J7: =C7-B7 -> -534097.04 | K7: =SUM($J$2:J7) -> 1896075.7
A8: Jul | B8: {=SUMPRODUCT((data!D2:D1001>=43647)*(data!D2:D1001<43678)*data!B2:B1001)} -> 6638609.2 | C8: {=SUMPRODUCT((data!D2:D1001>=44013)*(data!D2:D1001<44044)*data!B2:B1001)} -> 5242556.5 | D8: 10000000 | I8: Jul | J8: =C8-B8 -> -1396052.8 | K8: =SUM($J$2:J8) -> 500022.98
A9: Aug | B9: {=SUMPRODUCT((data!D2:D1001>=43678)*(data!D2:D1001<43709)*data!B2:B1001)} -> 3437450.1 | C9: {=SUMPRODUCT((data!D2:D1001>=44044)*(data!D2:D1001<44075)*data!B2:B1001)} -> 4714525.2 | I9: Aug | J9: =C9-B9 -> 1277075.1 | K9: =SUM($J$2:J9) -> 1777098
A10: Sep | B10: {=SUMPRODUCT((data!D2:D1001>=43709)*(data!D2:D1001<43739)*data!B2:B1001)} -> 4870060.6 | C10: {=SUMPRODUCT((data!D2:D1001>=44075)*(data!D2:D1001<44105)*data!B2:B1001)} -> 3778141.4 | I10: Sep | J10: =C10-B10 -> -1091919.2 | K10: =SUM($J$2:J10) -> 685178.87
A11: Oct | B11: {=SUMPRODUCT((data!D2:D1001>=43739)*(data!D2:D1001<43770)*data!B2:B1001)} -> 4372149.5 | C11: {=SUMPRODUCT((data!D2:D1001>=44105)*(data!D2:D1001<44136)*data!B2:B1001)} -> 4869726.9 | I11: Oct | J11: =C11-B11 -> 497577.3 | K11: =SUM($J$2:J11) -> 1182756.2
A12: Nov | B12: {=SUMPRODUCT((data!D2:D1001>=43770)*(data!D2:D1001<43800)*data!B2:B1001)} -> 2961318.6 | C12: {=SUMPRODUCT((data!D2:D1001>=44136)*(data!D2:D1001<44166)*data!B2:B1001)} -> 4734730.1 | I12: Nov | J12: =C12-B12 -> 1773411.5 | K12: =SUM($J$2:J12) -> 2956167.7
A13: Dec | B13: {=SUMPRODUCT((data!D2:D1001>=43800)*(data!D2:D1001<43831)*data!B2:B1001)} -> 8713776 | C13: {=SUMPRODUCT((data!D2:D1001>=44166)*(data!D2:D1001<44197)*data!B2:B1001)} -> 5884298.3 | D13: 10000000 | E13: 2019 | F13: 2020 | I13: Dec | J13: =C13-B13 -> -2829477.8 | K13: =SUM($J$2:J13) -> 126689.91
O24: Line chart
O25: Fake column for background
O26: Colors
O27: Data lable show series
O28: Legend custom number format
T143: Format axis > axis options > label > label position low
T144: invert if negative

Sheet 07_what_data_says
A2: Sum of order_value_EUR | B2: Column Labels
B3: 2019 | E3: 2020
A4: Row Labels | B4: Mobile | C4: PC | D4: Tablet | E4: Mobile | F4: PC | G4: Tablet
A5: Alyosha Meah | B5: 512800.89 | C5: 2022380.3 | D5: 495470.75 | E5: 93996.68 | F5: 1365493.7 | G5: 54446.5
A6: Amelina Piscopiello | B6: 253580.37 | C6: 3169565.8 | D6: 638875.84 | E6: 439504.7 | F6: 2107337.2 | G6: 46296.26
A7: Anita Woakes | B7: 165160.22 | C7: 1608477.2 | D7: 19930.04 | E7: 193137.13 | F7: 1520046 | G7: 110092.84
A8: Aurelie Wren | B8: 654933.67 | C8: 1440563.9 | D8: 89830.34 | E8: 290498.22 | F8: 2598897.9 | G8: 413829.11
A9: Avrit Chanders | B9: 454590.84 | C9: 1307572.3 | D9: 277322.94 | E9: 581163.51 | F9: 1839695.1 | G9: 252406.76
A10: Bank Coumbe | F10: 190166.35
A11: Bernadine Fullagar | B11: 78293.94 | C11: 953239.14 | D11: 37073.91 | F11: 814589.38
A12: Bertha Walbrook | B12: 280678.21 | C12: 286411.11 | D12: 178763.42 | E12: 120012.56 | F12: 199698.58
A13: Brynn Dempster | B13: 406772.54 | C13: 856472.03 | D13: 41805.53 | E13: 221010.85 | F13: 3053647.4 | G13: 179323.22
A14: Bunnie Tonbridge | B14: 307535.91 | C14: 851089.22 | D14: 114232.68 | E14: 239399.8 | F14: 1205614.1
A15: Caro Morfield | B15: 325331.99 | C15: 798196.14 | D15: 204484.61 | E15: 591358.8 | F15: 957366.41 | G15: 82116.31
A16: Case Desorts | C16: 297172.76 | F16: 193787.99
A17: Casie MacBain | B17: 80986.1 | C17: 1277243.9 | D17: 51407.3 | E17: 527020.25 | F17: 808468.52 | G17: 48922.42
A18: Cobby Andersen | C18: 39287.29 | F18: 232955.47
A19: Collin Mackness | B19: 76183.74 | C19: 152370.57 | E19: 211215.03 | F19: 169200.62
A20: Corene Shirer | B20: 544111.53 | C20: 2185710.3 | D20: 257879.35 | E20: 87513.27 | F20: 3781370.7 | G20: 40467.85
A21: Crysta Halls | B21: 203604.46 | C21: 2434315.5 | D21: 240171.57 | E21: 149028.5 | F21: 2088834 | G21: 38648.72
A22: Genevra Charrisson | B22: 112491.58 | C22: 2115123 | D22: 209344.07 | E22: 287715.07 | F22: 1574219.1 | G22: 34748.75
A23: Hortense Gerring | B23: 754664.13 | C23: 2167729.7 | D23: 308527.28 | E23: 477021.4 | F23: 1999025.6 | G23: 453248.85
A24: Jay Morefield | B24: 256388.08 | C24: 1598031.3 | D24: 83097.4 | E24: 77128.75 | F24: 977691 | G24: 114101.42
A25: Jocelyn Laurentino | B25: 104743.22 | C25: 998039.46 | D25: 569532.38 | F25: 1241235.3
A26: Joshua Prevost | C26: 459532.09 | E26: 185564.4 | F26: 246239.97 | G26: 44232.84
A27: Madelon Bront | B27: 460839.73 | C27: 1105178.5 | D27: 97063.22 | E27: 234994.63 | F27: 2015484.5 | G27: 36181.81
A28: Maighdiln Upcraft | B28: 467178.51 | C28: 2407774 | E28: 31161.76 | F28: 1099156.4 | G28: 134621.8
A29: Manuel Goudie | C29: 68745.86 | F29: 188568.66 | G29: 148530.26
A30: Mellicent Mattys | B30: 248195.54 | C30: 815694.01 | D30: 256542.88 | E30: 186397.6 | F30: 1097369.8 | G30: 106115.85
A31: Nero Harbisher | B31: 104152.15 | C31: 696744 | D31: 214983.15 | E31: 207751.43 | F31: 1950792.6 | G31: 50241.47
A32: Ora Grennan | B32: 590815.3 | C32: 2277726.9 | E32: 334106.41 | F32: 1884734.4 | G32: 150888.61
A33: Palm Wetherald | C33: 1036133.2 | E33: 306303.61 | F33: 891976.19
A34: Perri Aldersley | B34: 59163.79 | C34: 615903.28 | F34: 352763.8
A35: Shermy McGready | B35: 83141.47 | C35: 757666.74 | E35: 214701.97 | F35: 543438.09
A36: Smitty Culverhouse | B36: 246741.34 | C36: 1472738.4 | D36: 294472.77 | E36: 487744.33 | F36: 1989810.3
A37: Tarrah Castelletti | B37: 113586.11 | C37: 2328756.8 | D37: 145558 | E37: 127148.98 | F37: 1753805.3 | G37: 98320.37
A38: Wat Bowkley | B38: 116563.4 | C38: 732927.07 | D38: 368106.23 | F38: 1351323.9 | G38: 268798.69
A39: Winny Agnolo | B39: 153713.47 | C39: 1705590.5 | D39: 166004.16 | E39: 327852.52 | F39: 2322377.1
A40: Grand Total | B40: 8216942.2 | C40: 43040102 | D40: 5360479.8 | E40: 7230452.2 | F40: 46607181 | G40: 2906580.7
A45: Sum of order_value_EUR | B45: Column Labels
...

Sheet Sheet5
A1: month_name | B1: Dec
B3: year | C3: Values | J3: category | K3: Count of order_id | L3: Sum of order_value_EUR | M3: Count of order_id | N3: Sum of order_value_EUR
B4: 2019 | D4: 2020 | J4: Accessories | K4: 16 | L4: 2232817 | M4: 19 | N4: 2471113.7 | O4: =L4/K4 -> 139551.06 | P4: =N4/M4 -> 130058.61
A5: category | B5: Sum of order_value_EUR | C5: Sum of cost | D5: Sum of order_value_EUR | E5: Sum of cost | J5: Appliances | K5: 62 | L5: 7112586 | M5: 69 | N5: 8027082.7 | O5: =L5/K5 -> 114719.13 | P5: =N5/M5 -> 116334.53
A6: Accessories | B6: 448320.25 | C6: 361580.7 | J6: Beauty | K6: 61 | L6: 7214529.9 | M6: 54 | N6: 5354534 | O6: =L6/K6 -> 118270.98 | P6: =N6/M6 -> 99158.037
A7: Appliances | B7: 1336283.7 | C7: 1099808.5 | D7: 959641.12 | E7: 824432.42 | J7: Books | K7: 46 | L7: 5415804.5 | M7: 71 | N7: 7764174.4 | O7: =L7/K7 -> 117734.88 | P7: =N7/M7 -> 109354.57
A8: Beauty | B8: 661876.53 | C8: 562808.22 | D8: 527281.7 | E8: 427730.49 | J8: Clothing | K8: 85 | L8: 10194639 | M8: 70 | N8: 7467043.5 | O8: =L8/K8 -> 119936.93 | P8: =N8/M8 -> 106672.05
A9: Books | B9: 1222263 | C9: 988537.12 | D9: 752695.67 | E9: 643012.71 | J9: Electronics | K9: 68 | L9: 6858779.7 | M9: 66 | N9: 7623297.9 | O9: =L9/K9 -> 100864.41 | P9: =N9/M9 -> 115504.51
A10: Clothing | B10: 1527668.1 | C10: 1288192.4 | D10: 1050478.6 | E10: 878546.06 | J10: Games | K10: 74 | L10: 8124122.5 | M10: 65 | N10: 7197501 | O10: =L10/K10 -> 109785.44 | P10: =N10/M10 -> 110730.78
A11: Electronics | B11: 957346.47 | C11: 794608.63 | D11: 700183.93 | E11: 583150.67 | J11: Other | K11: 10 | L11: 1201110.5 | M11: 19 | N11: 2061872.7 | O11: =L11/K11 -> 120111.05 | P11: =N11/M11 -> 108519.61
A12: Games | B12: 705668.64 | C12: 577330.77 | D12: 197996.9 | E12: 165423.43 | J12: Outdoors | K12: 21 | L12: 2302350.9 | M12: 29 | N12: 3636724.6 | O12: =L12/K12 -> 109635.75 | P12: =N12/M12 -> 125404.3
A13: Other | B13: 383996.76 | C13: 304701.43 | D13: 290551.74 | E13: 239530.86 | J13: Smartphones | K13: 47 | L13: 5960784.8 | M13: 48 | N13: 5140869.9 | O13: =L13/K13 -> 126825.21 | P13: =N13/M13 -> 107101.46
A14: Outdoors | B14: 360846.09 | C14: 290470.06 | D14: 583005.87 | E14: 473664.25 | J14: Grand Total | K14: 490 | L14: 56617524 | M14: 510 | N14: 56744214 | O14: =L14/K14 -> 115545.97 | P14: =N14/M14 -> 111263.17
A15: Smartphones | B15: 1109506.4 | C15: 931064.7 | D15: 822462.77 | E15: 678011.15
A16: Grand Total | B16: 8713776 | C16: 7199102.5 | D16: 5884298.3 | E16: 4913502
A18: category | B18: Sum of order_value_EUR | C18: Sum of order_value_EUR | D18: Count of order_id
A19: Accessories | B19: 2232817 | C19: 2471113.7 | D19: =C19-B19 -> 238296.66
A20: Appliances | B20: 7112586 | C20: 8027082.7 | D20: =C20-B20 -> 914496.75
A21: Beauty | B21: 7214529.9 | C21: 5354534 | D21: =C21-B21 -> -1859995.9
A22: Books | B22: 5415804.5 | C22: 7764174.4 | D22: =C22-B22 -> 2348369.9
A23: Clothing | B23: 10194639 | C23: 7467043.5 | D23: =C23-B23 -> -2727595.1
A24: Electronics | B24: 6858779.7 | C24: 7623297.9 | D24: =C24-B24 -> 764518.14
A25: Games | B25: 8124122.5 | C25: 7197501 | D25: =C25-B25 -> -926621.49
A26: Other | B26: 1201110.5 | C26: 2061872.7 | D26: =C26-B26 -> 860762.12 | H26: 2019 | I26: 2020
A27: Outdoors | B27: 2302350.9 | C27: 3636724.6 | D27: =C27-B27 -> 1334373.7 | G27: A | H27: 0.2 | I27: 0.29
A28: Smartphones | B28: 5960784.8 | C28: 5140869.9 | D28: =C28-B28 -> -819914.84 | G28: B | H28: 0.26 | I28: 0.2
A29: Grand Total | B29: 56617524 | C29: 56744214 | G29: C | H29: =1-SUM(H27:H28) -> 0.54 | I29: =1-SUM(I27:I28) -> 0.51
B33: 2019 | C33: 56617524
B34: Accessories | C34: 238296.66
B35: Appliances | C35: 914496.75
B36: Beauty | C36: -1859995.9
B37: Books | C37: 2348369.9
B38: Clothing | C38: -2727595.1
B39: Electronics | C39: 764518.14
B40: Games | C40: -926621.49
B41: Other | C41: 860762.12
B42: Outdoors | C42: 1334373.7
B43: Smartphones | C43: -819914.84
B44: 2020 | C44: =SUM(C33:C43) -> 56744214
A53: category | B53: Beauty
...

Sheet Sheet1
A3: Sum of order_value_EUR | B3: year
A4: customer_name | B4: 2019 | C4: 2020 | D4: Diff
A5: Abbott, Roberts and Torp | B5: 41805.53 | C5: 149372.32 | D5: =C5-B5 -> 107566.79 | E5: Old - Increase | G5: Old - Increase | H5: =SUMIFS(D:D,E:E,G5) -> 11987392
A6: Altenwerth-Konopelski | B6: 1247594.4 | C6: 1276614 | D6: =C6-B6 -> 29019.62 | E6: Old - Increase | G6: Old - reduce | H6: =SUMIFS(D:D,E:E,G6) -> -12211712
A7: Armstrong-Little | B7: 412995.68 | C7: 1645291.8 | D7: =C7-B7 -> 1232296.1 | E7: Old - Increase | G7: New | H7: =SUMIFS(D:D,E:E,G7) -> 504092
A8: Bashirian, Okuneva and Bechtelar | B8: 769774.07 | C8: 584176.6 | D8: =C8-B8 -> -185597.47 | E8: Old - reduce | G8: Loss | H8: =SUMIFS(D:D,E:E,G8) -> -153082.16
A9: Baumbach Group | B9: 106142.65 | C9: 65397.28 | D9: =C9-B9 -> -40745.37 | E9: Old - reduce
A10: Christiansen, Donnelly and Bechtelar | B10: 1409447.1 | C10: 538832.19 | D10: =C10-B10 -> -870614.87 | E10: Old - reduce
A11: Connelly-Mohr | B11: 429417.28 | C11: 201537.12 | D11: =C11-B11 -> -227880.16 | E11: Old - reduce
A12: Considine-Fisher | B12: 605245.71 | C12: 721475.52 | D12: =C12-B12 -> 116229.81 | E12: Old - Increase
A13: Corwin and Sons | B13: 1120009.6 | C13: 736058.72 | D13: =C13-B13 -> -383950.91 | E13: Old - reduce
A14: Dibbert Inc | B14: 801090.86 | C14: 1074305.4 | D14: =C14-B14 -> 273214.54 | E14: Old - Increase
A15: Dickinson, Hyatt and Berge | B15: 1288115.3 | C15: 1418615 | D15: =C15-B15 -> 130499.64 | E15: Old - Increase
A16: Farrell, Swaniawski and Crist | B16: 618952.74 | C16: 982696.22 | D16: =C16-B16 -> 363743.48 | E16: Old - Increase
A17: Fisher, Morar and Skiles | B17: 280939.26 | C17: 585351.25 | D17: =C17-B17 -> 304411.99 | E17: Old - Increase
A18: Franecki-White | B18: 471792.25 | C18: 404854.26 | D18: =C18-B18 -> -66937.99 | E18: Old - reduce
A19: Friesen and Sons | B19: 300951.26 | C19: 331837.25 | D19: =C19-B19 -> 30885.99 | E19: Old - Increase
A20: Friesen-Rath | B20: 1103549.8 | C20: 992278.48 | D20: =C20-B20 -> -111271.28 | E20: Old - reduce
... A23: Goldner-Dibbert | B23: 384927.23 | C23: 523544.06 | D23: =C23-B23 -> 138616.83 | E23: Old - Increase
A24: Gorczany-Lehner | C24: 33724.53 | D24: =C24-B24 -> 33724.53 | E24: New
A25: Hamill, Kulas and Roob | B25: 743651.32 | C25: 696628.95 | D25: =C25-B25 -> -47022.37 | E25: Old - reduce
A26: Hane Inc | B26: 40148.49 | C26: 420960.89 | D26: =C26-B26 -> 380812.4 | E26: Old - Increase
A27: Hartmann, Hane and Pfannerstill | B27: 890011.39 | C27: 115840.76 | D27: =C27-B27 -> -774170.63 | E27: Old - reduce
A28: Heaney, Gulgowski and Kshlerin | B28: 234961.46 | C28: 207248.76 | D28: =C28-B28 -> -27712.7 | E28: Old - reduce
A29: Hegmann Group | B29: 913880.24 | C29: 955056.87 | D29: =C29-B29 -> 41176.63 | E29: Old - Increase
A30: Hermiston, Simonis and Wisoky | B30: 357211.71 | C30: 714702.47 | D30: =C30-B30 -> 357490.76 | E30: Old - Increase
A31: Hessel-Stiedemann | B31: 2207495.9 | C31: 4304568 | D31: =C31-B31 -> 2097072 | E31: Old - Increase
A32: Hilll-Vandervort | B32: 1033860.3 | C32: 796798.66 | D32: =C32-B32 -> -237061.61 | E32: Old - reduce
A33: Homenick-Marvin | B33: 188689.18 | C33: 322431.7 | D33: =C33-B33 -> 133742.52 | E33: Old - Increase
A34: Jacobson, Marvin and Brown | B34: 593747.16 | C34: 494220.85 | D34: =C34-B34 -> -99526.31 | E34: Old - reduce
A35: Johns and Sons | B35: 9344591.8 | C35: 7015665.5 | D35: =C35-B35 -> -2328926.4 | E35: Old - reduce
A36: Keeling, Monahan and Pollich | B36: 629989.66 | C36: 759680.04 | D36: =C36-B36 -> 129690.38 | E36: Old - Increase
... A42: Leffler, Prohaska and Streich | B42: 214060.65 | C42: 556210.76 | D42: =C42-B42 -> 342150.11 | E42: Old - Increase
A43: Lind, Mueller and Stoltenberg | B43: 57115.99 | D43: =C43-B43 -> -57115.99 | E43: Loss
A44: Littel-Blick | B44: 95966.17 | D44: =C44-B44 -> -95966.17 | E44: Loss
A45: Lubowitz, McLaughlin and Erdman | B45: 185183.58 | C45: 442586.52 | D45: =C45-B45 -> 257402.94 | E45: Old - Increase
A46: Lueilwitz, Kerluke and Lesch | B46: 223549.31 | C46: 208157.79 | D46: =C46-B46 -> -15391.52 | E46: Old - reduce
A47: Marquardt-Kuvalis | B47: 91842.59 | C47: 104711.22 | D47: =C47-B47 -> 12868.63 | E47: Old - Increase
A48: McClure Inc | B48: 638834.95 | C48: 589170.06 | D48: =C48-B48 -> -49664.89 | E48: Old - reduce
A49: McGlynn-Bergstrom | B49: 433475.01 | C49: 750555.35 | D49: =C49-B49 -> 317080.34 | E49: Old - Increase
...
